Invalid HTTP_HOST header: 'ade8-102-89-23-63.ngrok-free.app'. You may need to add 'ade8-102-89-23-63.ngrok-free.app' to ALLOWED_HOSTS.
Traceback (most recent call last):
  File "C:\Users\User\Desktop\Projects\GLISSUS\home_venv\lib\site-packages\django\core\handlers\exception.py", line 55, in inner
    response = get_response(request)
  File "C:\Users\User\Desktop\Projects\GLISSUS\home_venv\lib\site-packages\django\utils\deprecation.py", line 133, in __call__
    response = self.process_request(request)
  File "C:\Users\User\Desktop\Projects\GLISSUS\home_venv\lib\site-packages\django\middleware\common.py", line 48, in process_request
    host = request.get_host()
  File "C:\Users\User\Desktop\Projects\GLISSUS\home_venv\lib\site-packages\django\http\request.py", line 167, in get_host
    raise DisallowedHost(msg)
django.core.exceptions.DisallowedHost: Invalid HTTP_HOST header: 'ade8-102-89-23-63.ngrok-free.app'. You may need to add 'ade8-102-89-23-63.ngrok-free.app' to ALLOWED_HOSTS.
Invalid HTTP_HOST header: 'ade8-102-89-23-63.ngrok-free.app'. You may need to add 'ade8-102-89-23-63.ngrok-free.app' to ALLOWED_HOSTS.
Traceback (most recent call last):
  File "C:\Users\User\Desktop\Projects\GLISSUS\home_venv\lib\site-packages\django\core\handlers\exception.py", line 55, in inner
    response = get_response(request)
  File "C:\Users\User\Desktop\Projects\GLISSUS\home_venv\lib\site-packages\django\utils\deprecation.py", line 133, in __call__
    response = self.process_request(request)
  File "C:\Users\User\Desktop\Projects\GLISSUS\home_venv\lib\site-packages\django\middleware\common.py", line 48, in process_request
    host = request.get_host()
  File "C:\Users\User\Desktop\Projects\GLISSUS\home_venv\lib\site-packages\django\http\request.py", line 167, in get_host
    raise DisallowedHost(msg)
django.core.exceptions.DisallowedHost: Invalid HTTP_HOST header: 'ade8-102-89-23-63.ngrok-free.app'. You may need to add 'ade8-102-89-23-63.ngrok-free.app' to ALLOWED_HOSTS.
Internal Server Error: /chatbot/incoming/
Traceback (most recent call last):
  File "C:\Users\User\Desktop\Projects\GLISSUS\home_venv\lib\site-packages\django\core\handlers\exception.py", line 55, in inner
    response = get_response(request)
  File "C:\Users\User\Desktop\Projects\GLISSUS\home_venv\lib\site-packages\django\core\handlers\base.py", line 197, in _get_response
    response = wrapped_callback(request, *callback_args, **callback_kwargs)
  File "C:\Users\User\Desktop\Projects\GLISSUS\home_venv\lib\site-packages\django\views\decorators\csrf.py", line 56, in wrapper_view
    return view_func(*args, **kwargs)
  File "C:\Users\User\Desktop\Projects\GLISSUS\Blog_DuLoft\chatbot\views.py", line 76, in handle_incoming_messages
    response = send_message(sender_number, response_message)
  File "C:\Users\User\Desktop\Projects\GLISSUS\Blog_DuLoft\chatbot\views.py", line 55, in send_message
    client.messages.create(
  File "C:\Users\User\Desktop\Projects\GLISSUS\home_venv\lib\site-packages\twilio\rest\api\v2010\account\message\__init__.py", line 565, in create
    payload = self._version.create(
  File "C:\Users\User\Desktop\Projects\GLISSUS\home_venv\lib\site-packages\twilio\base\version.py", line 465, in create
    return self._parse_create(method, uri, response)
  File "C:\Users\User\Desktop\Projects\GLISSUS\home_venv\lib\site-packages\twilio\base\version.py", line 436, in _parse_create
    raise self.exception(method, uri, response, "Unable to create record")
twilio.base.exceptions.TwilioRestException: 
[31m[49mHTTP Error[0m [37m[49mYour request was:[0m

[36m[49mPOST /Accounts/AC2475f0593a1fdf0f82c368182a5564ad/Messages.json[0m

[37m[49mTwilio returned the following information:[0m

[34m[49mUnable to create record: The 'From' phone number +14155238886 is not a valid message-capable Twilio phone number for this destination.[0m

[37m[49mMore information may be available here:[0m

[34m[49mhttps://www.twilio.com/docs/errors/21606[0m


Internal Server Error: /chatbot/incoming/
Traceback (most recent call last):
  File "C:\Users\User\Desktop\Projects\GLISSUS\home_venv\lib\site-packages\django\core\handlers\exception.py", line 55, in inner
    response = get_response(request)
  File "C:\Users\User\Desktop\Projects\GLISSUS\home_venv\lib\site-packages\django\core\handlers\base.py", line 197, in _get_response
    response = wrapped_callback(request, *callback_args, **callback_kwargs)
  File "C:\Users\User\Desktop\Projects\GLISSUS\home_venv\lib\site-packages\django\views\decorators\csrf.py", line 56, in wrapper_view
    return view_func(*args, **kwargs)
  File "C:\Users\User\Desktop\Projects\GLISSUS\Blog_DuLoft\chatbot\views.py", line 76, in handle_incoming_messages
    response = send_message(sender_number, response_message)
  File "C:\Users\User\Desktop\Projects\GLISSUS\Blog_DuLoft\chatbot\views.py", line 55, in send_message
    client.messages.create(
  File "C:\Users\User\Desktop\Projects\GLISSUS\home_venv\lib\site-packages\twilio\rest\api\v2010\account\message\__init__.py", line 565, in create
    payload = self._version.create(
  File "C:\Users\User\Desktop\Projects\GLISSUS\home_venv\lib\site-packages\twilio\base\version.py", line 465, in create
    return self._parse_create(method, uri, response)
  File "C:\Users\User\Desktop\Projects\GLISSUS\home_venv\lib\site-packages\twilio\base\version.py", line 436, in _parse_create
    raise self.exception(method, uri, response, "Unable to create record")
twilio.base.exceptions.TwilioRestException: 
[31m[49mHTTP Error[0m [37m[49mYour request was:[0m

[36m[49mPOST /Accounts/AC2475f0593a1fdf0f82c368182a5564ad/Messages.json[0m

[37m[49mTwilio returned the following information:[0m

[34m[49mUnable to create record: The 'From' phone number +14155238886 is not a valid message-capable Twilio phone number for this destination.[0m

[37m[49mMore information may be available here:[0m

[34m[49mhttps://www.twilio.com/docs/errors/21606[0m


Internal Server Error: /chatbot/incoming/
Traceback (most recent call last):
  File "C:\Users\User\Desktop\Projects\GLISSUS\home_venv\lib\site-packages\django\core\handlers\exception.py", line 55, in inner
    response = get_response(request)
  File "C:\Users\User\Desktop\Projects\GLISSUS\home_venv\lib\site-packages\django\core\handlers\base.py", line 197, in _get_response
    response = wrapped_callback(request, *callback_args, **callback_kwargs)
  File "C:\Users\User\Desktop\Projects\GLISSUS\home_venv\lib\site-packages\django\views\decorators\csrf.py", line 56, in wrapper_view
    return view_func(*args, **kwargs)
  File "C:\Users\User\Desktop\Projects\GLISSUS\Blog_DuLoft\chatbot\views.py", line 76, in handle_incoming_messages
    response = send_message(sender_number, response_message)
  File "C:\Users\User\Desktop\Projects\GLISSUS\Blog_DuLoft\chatbot\views.py", line 55, in send_message
    client.messages.create(
  File "C:\Users\User\Desktop\Projects\GLISSUS\home_venv\lib\site-packages\twilio\rest\api\v2010\account\message\__init__.py", line 565, in create
    payload = self._version.create(
  File "C:\Users\User\Desktop\Projects\GLISSUS\home_venv\lib\site-packages\twilio\base\version.py", line 465, in create
    return self._parse_create(method, uri, response)
  File "C:\Users\User\Desktop\Projects\GLISSUS\home_venv\lib\site-packages\twilio\base\version.py", line 436, in _parse_create
    raise self.exception(method, uri, response, "Unable to create record")
twilio.base.exceptions.TwilioRestException: 
[31m[49mHTTP Error[0m [37m[49mYour request was:[0m

[36m[49mPOST /Accounts/AC2475f0593a1fdf0f82c368182a5564ad/Messages.json[0m

[37m[49mTwilio returned the following information:[0m

[34m[49mUnable to create record: The 'From' phone number +14155238886 is not a valid message-capable Twilio phone number for this destination.[0m

[37m[49mMore information may be available here:[0m

[34m[49mhttps://www.twilio.com/docs/errors/21606[0m


Internal Server Error: /chatbot/incoming/
Traceback (most recent call last):
  File "C:\Users\User\Desktop\Projects\GLISSUS\home_venv\lib\site-packages\django\core\handlers\exception.py", line 55, in inner
    response = get_response(request)
  File "C:\Users\User\Desktop\Projects\GLISSUS\home_venv\lib\site-packages\django\core\handlers\base.py", line 197, in _get_response
    response = wrapped_callback(request, *callback_args, **callback_kwargs)
  File "C:\Users\User\Desktop\Projects\GLISSUS\home_venv\lib\site-packages\django\views\decorators\csrf.py", line 56, in wrapper_view
    return view_func(*args, **kwargs)
  File "C:\Users\User\Desktop\Projects\GLISSUS\Blog_DuLoft\chatbot\views.py", line 76, in handle_incoming_messages
    response = send_message(sender_number, response_message)
  File "C:\Users\User\Desktop\Projects\GLISSUS\Blog_DuLoft\chatbot\views.py", line 55, in send_message
    client.messages.create(
  File "C:\Users\User\Desktop\Projects\GLISSUS\home_venv\lib\site-packages\twilio\rest\api\v2010\account\message\__init__.py", line 565, in create
    payload = self._version.create(
  File "C:\Users\User\Desktop\Projects\GLISSUS\home_venv\lib\site-packages\twilio\base\version.py", line 465, in create
    return self._parse_create(method, uri, response)
  File "C:\Users\User\Desktop\Projects\GLISSUS\home_venv\lib\site-packages\twilio\base\version.py", line 436, in _parse_create
    raise self.exception(method, uri, response, "Unable to create record")
twilio.base.exceptions.TwilioRestException: 
[31m[49mHTTP Error[0m [37m[49mYour request was:[0m

[36m[49mPOST /Accounts/AC2475f0593a1fdf0f82c368182a5564ad/Messages.json[0m

[37m[49mTwilio returned the following information:[0m

[34m[49mUnable to create record: Invalid From and To pair. From and To should be of the same channel[0m

[37m[49mMore information may be available here:[0m

[34m[49mhttps://www.twilio.com/docs/errors/21910[0m


