Internal Server Error: /account/login/
Traceback (most recent call last):
  File "C:\Users\User\Desktop\Projects\GLISSUS\home_venv\lib\site-packages\django\core\handlers\exception.py", line 55, in inner
    response = get_response(request)
  File "C:\Users\User\Desktop\Projects\GLISSUS\home_venv\lib\site-packages\django\core\handlers\base.py", line 197, in _get_response
    response = wrapped_callback(request, *callback_args, **callback_kwargs)
  File "C:\Users\User\Desktop\Projects\GLISSUS\Blog_DuLoft\accounts\views.py", line 10, in login
    login_url = f"{settings.SOS['ROOT']}/user/login/?next={reverse('blog_post')}"
  File "C:\Users\User\Desktop\Projects\GLISSUS\home_venv\lib\site-packages\django\conf\__init__.py", line 104, in __getattr__
    val = getattr(_wrapped, name)
AttributeError: 'Settings' object has no attribute 'SOS'
